2019-10-04 14:45:16,649 [ERROR]  Experienced exception while trying to serve
Traceback (most recent call last):
  File "/home/dennis/chatenv/lib/python3.6/site-packages/sanic/app.py", line 1096, in run
    serve(**server_settings)
  File "/home/dennis/chatenv/lib/python3.6/site-packages/sanic/server.py", line 742, in serve
    trigger_events(before_start, loop)
  File "/home/dennis/chatenv/lib/python3.6/site-packages/sanic/server.py", line 604, in trigger_events
    loop.run_until_complete(result)
  File "uvloop/loop.pyx", line 1417, in uvloop.loop.Loop.run_until_complete
  File "/home/dennis/chatenv/lib/python3.6/site-packages/rasa/core/run.py", line 199, in load_agent_on_start
    action_endpoint=endpoints.action,
  File "/home/dennis/chatenv/lib/python3.6/site-packages/rasa/core/agent.py", line 233, in load_agent
    remote_storage=remote_storage,
  File "/home/dennis/chatenv/lib/python3.6/site-packages/rasa/core/agent.py", line 878, in load_local_model
    remote_storage=remote_storage,
  File "/home/dennis/chatenv/lib/python3.6/site-packages/rasa/core/agent.py", line 364, in load
    interpreter = NaturalLanguageInterpreter.create(nlu_model)
  File "/home/dennis/chatenv/lib/python3.6/site-packages/rasa/core/interpreter.py", line 45, in create
    return RasaNLUInterpreter(model_directory=obj)
  File "/home/dennis/chatenv/lib/python3.6/site-packages/rasa/core/interpreter.py", line 246, in __init__
    self._load_interpreter()
  File "/home/dennis/chatenv/lib/python3.6/site-packages/rasa/core/interpreter.py", line 264, in _load_interpreter
    self.interpreter = Interpreter.load(self.model_directory)
  File "/home/dennis/chatenv/lib/python3.6/site-packages/rasa/nlu/model.py", line 302, in load
    return Interpreter.create(model_metadata, component_builder, skip_validation)
  File "/home/dennis/chatenv/lib/python3.6/site-packages/rasa/nlu/model.py", line 329, in create
    component_meta, model_metadata.model_dir, model_metadata, **context
  File "/home/dennis/chatenv/lib/python3.6/site-packages/rasa/nlu/components.py", line 433, in load_component
    component_meta, model_dir, model_metadata, cached_component, **context
  File "/home/dennis/chatenv/lib/python3.6/site-packages/rasa/nlu/registry.py", line 181, in load_component_by_meta
    component_meta, model_dir, metadata, cached_component, **kwargs
  File "/home/dennis/chatenv/lib/python3.6/site-packages/rasa/nlu/classifiers/embedding_intent_classifier.py", line 708, in load
    b_in = tf.get_collection("intent_placeholder")[0]
IndexError: list index out of range
